Workbook

Sheet Hoja 1
A1: fecha | B1: hora | C1: temp | D1: velviento | E1: dirviento | F1: direct_radiation_openmeteo | G1: hora solar
A2: 45444 | B2: 0 | C2: 14.645 | D2: 3.5455887 | E2: 23.962492 | F2: 0 | G2: =B2+0.15 -> 0.15
A3: 45444 | B3: 1 | C3: 14.594999 | D3: 4.0249224 | E3: 10.304792 | F3: 0 | G3: =B3+0.15 -> 1.15
A4: 45444 | B4: 2 | C4: 14.495 | D4: 5.7712388 | E4: 356.42374 | F4: 0 | G4: =B4+0.15 -> 2.15
A5: 45444 | B5: 3 | C5: 13.495 | D5: 6.1936741 | E5: 215.53777 | F5: 0 | G5: =B5+0.15 -> 3.15
A6: 45444 | B6: 4 | C6: 12.645 | D6: 5.6233797 | E6: 230.19447 | F6: 0 | G6: =B6+0.15 -> 4.15
A7: 45444 | B7: 5 | C7: 12.395 | D7: 7.1457958 | E7: 229.08571 | F7: 0.033950329 | G7: =B7+0.15 -> 5.15
A8: 45444 | B8: 6 | C8: 13.795 | D8: 4.0249224 | E8: 206.56499 | F8: 51.700218 | G8: =B8+0.15 -> 6.15
A9: 45444 | B9: 7 | C9: 14.945 | D9: 4.6102495 | E9: 231.34016 | F9: 4.1932335 | G9: =B9+0.15 -> 7.15
A10: 45444 | B10: 8 | C10: 15.795 | D10: 6.5693827 | E10: 279.46225 | F10: 5.4483795 | G10: =B10+0.15 -> 8.15
A11: 45444 | B11: 9 | C11: 16.545 | D11: 5.9372721 | E11: 284.03625 | F11: 0.28465652 | G11: =B11+0.15 -> 9.15
A12: 45444 | B12: 10 | C12: 16.594999 | D12: 5.5069408 | E12: 281.30991 | F12: -0.31522751 | G12: =B12+0.15 -> 10.15
A13: 45444 | B13: 11 | C13: 15.995 | D13: 5.3999996 | E13: 360 | F13: 0.15647507 | G13: =B13+0.15 -> 11.15
... A457: 45462 | B457: 23 | C457: 16.994999 | D457: 12.181624 | E457: 235.84026 | F457: 0 | G457: =B457+0.15 -> 23.15

Sheet Hoja 2
A1: fecha | B1: hora | C1: temp | D1: velviento | E1: dirviento | F1: hora solar
A2: 45444 | B2: 0 | C2: 13 | D2: 6 | E2: 318 | F2: 0.15
A3: 45444 | B3: 1 | C3: 13 | D3: 5 | E3: 315 | F3: 1.15
A4: 45444 | B4: 2 | C4: 13 | D4: 6 | E4: 312 | F4: 2.15
A5: 45444 | B5: 3 | C5: 13 | D5: 6 | E5: 301 | F5: 3.15
A6: 45444 | B6: 4 | C6: 13 | D6: 6 | E6: 297 | F6: 4.15
A7: 45444 | B7: 5 | C7: 13 | D7: 7 | E7: 291 | F7: 5.15
A8: 45444 | B8: 6 | C8: 13 | D8: 6 | E8: 284 | F8: 6.15
A9: 45444 | B9: 7 | C9: 14 | D9: 6 | E9: 289 | F9: 7.15
A10: 45444 | B10: 8 | C10: 14 | D10: 6 | E10: 300 | F10: 8.15
A11: 45444 | B11: 9 | C11: 15 | D11: 7 | E11: 313 | F11: 9.15
A12: 45444 | B12: 10 | C12: 16 | D12: 8 | E12: 333 | F12: 10.15
A13: 45444 | B13: 11 | C13: 16 | D13: 11 | E13: 345 | F13: 11.15
... A457: 45462 | B457: 23 | C457: 15 | D457: 4 | E457: 271 | F457: 23.15

Sheet Hoja 3
A1: fecha | B1: hora | C1: temp | D1: velviento | E1: dirviento | F1: hora solar
A2: 2024-06-01 | B2: 0 | C2: 14.7 | D2: 9 | E2: 30 | F2: 0.15
A3: 2024-06-01 | B3: 1 | C3: 14.5 | D3: 7.4 | E3: 347 | F3: 1.15
A4: 2024-06-01 | B4: 2 | C4: 14.1 | D4: 7.4 | E4: 260 | F4: 2.15
A5: 2024-06-01 | B5: 3 | C5: 13.8 | D5: 7.4 | E5: 219 | F5: 3.15
A6: 2024-06-01 | B6: 4 | C6: 13.7 | D6: 7.4 | E6: 228 | F6: 4.15
A7: 2024-06-01 | B7: 5 | C7: 13.6 | D7: 7.4 | E7: 226 | F7: 5.15
A8: 2024-06-01 | B8: 6 | C8: 14 | D8: 8 | E8: 210 | F8: 6.15
A9: 2024-06-01 | B9: 7 | C9: 16.1 | D9: 7.4 | E9: 247 | F9: 7.15
A10: 2024-06-01 | B10: 8 | C10: 16.3 | D10: 7.4 | E10: 283 | F10: 8.15
A11: 2024-06-01 | B11: 9 | C11: 16.5 | D11: 9.3 | E11: 326 | F11: 9.15
A12: 2024-06-01 | B12: 10 | C12: 16.2 | D12: 11.1 | E12: 316 | F12: 10.15
A13: 2024-06-01 | B13: 11 | C13: 16.5 | D13: 11.1 | E13: 334 | F13: 11.15
... A457: 2024-06-19 | B457: 23 | C457: 16.4 | D457: 14.8 | E457: 260 | F457: 23.15
A458: 2024-06-20 | C458: 16.7 | D458: 17 | E458: 280

Sheet Hoja 4
A1: fecha | B1: hora | C1: temp | D1: velviento | E1: dirviento | F1: hora solar | P1: DNI (W/m²) | Q1: UV
A2: 2024-06-01 | B2: 0 | C2: 15.6 | D2: 2.8 | E2: 358 | F2: 0.15 | P2: 0 | Q2: 0
A3: 2024-06-01 | B3: 1 | C3: 15.6 | D3: 2.4 | E3: 348 | F3: 1.15 | P3: 0 | Q3: 0
A4: 2024-06-01 | B4: 2 | C4: 15.6 | D4: 2.4 | E4: 332 | F4: 2.15 | P4: 0 | Q4: 0
A5: 2024-06-01 | B5: 3 | C5: 15.2 | D5: 2.8 | E5: 320 | F5: 3.15 | P5: 0 | Q5: 0
A6: 2024-06-01 | B6: 4 | C6: 15.2 | D6: 3.6 | E6: 322 | F6: 4.15 | P6: 0 | Q6: 0
A7: 2024-06-01 | B7: 5 | C7: 14.8 | D7: 3.6 | E7: 326 | F7: 5.15 | P7: 197 | Q7: 1.2
A8: 2024-06-01 | B8: 6 | C8: 14.8 | D8: 3.2 | E8: 328 | F8: 6.15 | P8: 542 | Q8: 1.3
A9: 2024-06-01 | B9: 7 | C9: 14.8 | D9: 2.8 | E9: 332 | F9: 7.15 | P9: 702 | Q9: 1.5
A10: 2024-06-01 | B10: 8 | C10: 15.2 | D10: 3.2 | E10: 346 | F10: 8.15 | P10: 796 | Q10: 2.6
A11: 2024-06-01 | B11: 9 | C11: 15.6 | D11: 3.6 | E11: 0 | F11: 9.15 | P11: 855 | Q11: 4.2
A12: 2024-06-01 | B12: 10 | C12: 15.9 | D12: 3.2 | E12: 2 | F12: 10.15 | P12: 892 | Q12: 3.9
A13: 2024-06-01 | B13: 11 | C13: 15.9 | D13: 3.2 | E13: 4 | F13: 11.15 | P13: 913 | Q13: 5.9
... A457: 2024-06-19 | B457: 23 | C457: 17.4 | D457: 6 | E457: 274 | F457: 23.15 | P457: 0 | Q457: 0

Sheet Medias
A1: fecha | B1: hora | C1: temp | D1: velviento | E1: dirviento | F1: radiacion solar | G1: hora solar
A2: 45444 | B2: 0 | C2: 14.981667 | D2: 5.1151962 | E2: 137.32083 | G2: 0
A3: 45444 | B3: 1 | C3: 14.898333 | D3: 4.6083075 | E3: 235.1016 | G3: 1
A4: 45444 | B4: 2 | C4: 14.731667 | D4: 5.1904129 | E4: 316.14125 | G4: 2
A5: 45444 | B5: 3 | C5: 14.165 | D5: 5.464558 | E5: 251.51259 | G5: 3
A6: 45444 | B6: 4 | C6: 13.848333 | D6: 5.5411266 | E6: 260.06482 | G6: 4
A7: 45444 | B7: 5 | C7: 13.598333 | D7: 6.0485986 | E7: 260.3619 | G7: 5
A8: 45444 | B8: 6 | C8: 14.198333 | D8: 5.0749741 | E8: 248.18833 | G8: 6
A9: 45444 | B9: 7 | C9: 15.281667 | D9: 4.9367498 | E9: 270.11339 | G9: 7
A10: 45444 | B10: 8 | C10: 15.765 | D10: 5.7231276 | E10: 302.82075 | G10: 8
A11: 45444 | B11: 9 | C11: 16.215 | D11: 6.2790907 | E11: 203.34542 | G11: 9
A12: 45444 | B12: 10 | C12: 16.231666 | D12: 6.6023136 | E12: 199.76997 | G12: 10
A13: 45444 | B13: 11 | C13: 16.131667 | D13: 6.5666665 | E13: 232.66667 | G13: 11
... A25: 45444 | B25: 23 | C25: 15.631667 | D25: 6.7984721 | E25: 144.9492 | G25: 23
A26: 45445 | B26: 0 | C26: 15.731667 | D26: 9.5654348 | E26: 142.12815 | G26: =B26+0.15 -> 0.15
A27: 45445 | B27: 1 | C27: 15.431667 | D27: 6.1390509 | E27: 240.60357 | G27: =B27+0.15 -> 1.15
A28: 45445 | B28: 2 | C28: 14.998333 | D28: 5.7082461 | E28: 89.632395 | G28: =B28+0.15 -> 2.15
A29: 45445 | B29: 3 | C29: 14.931667 | D29: 5.5365391 | E29: 93.052425 | G29: =B29+0.15 -> 3.15
A30: 45445 | B30: 4 | C30: 14.948333 | D30: 5.4987956 | E30: 96.084646 | G30: =B30+0.15 -> 4.15
A31: 45445 | B31: 5 | C31: 14.965 | D31: 3.9818614 | E31: 144.28999 | G31: =B31+0.15 -> 5.15
A32: 45445 | B32: 6 | C32: 15.515 | D32: 6.4705633 | E32: 115.2685 | G32: =B32+0.15 -> 6.15
A33: 45445 | B33: 7 | C33: 16.265 | D33: 5.0867918 | E33: 89.873203 | G33: =B33+0.15 -> 7.15
A34: 45445 | B34: 8 | C34: 16.631666 | D34: 7.8460445 | E34: 121.94212 | G34: =B34+0.15 -> 8.15
A35: 45445 | B35: 9 | C35: 16.815 | D35: 5.6766356 | E35: 73.478338 | G35: =B35+0.15 -> 9.15
A36: 45445 | B36: 10 | C36: 17.431666 | D36: 8.1550835 | E36: 60.89226 | G36: =B36+0.15 -> 10.15
A37: 45445 | B37: 11 | C37: 17.665 | D37: 10.959027 | E37: 55.229786 | G37: =B37+0.15 -> 11.15
... A457: 45462 | B457: 23 | C457: 16.931666 | D457: 10.993875 | E457: 256.61342 | G457: =B457+0.15 -> 23.15

Sheet AnalisisTemp 
A1: ='Hoja 1'!C1 -> temp | B1: ='Hoja 2'!C1 -> temp | C1: ='Hoja 3'!C1 -> temp | D1: ='Hoja 4'!C1 -> temp | E1: MEDIA | F1: DESVI. TIPICA | G1: VARIANZA | H1: RANGO | I1: MEDIANA | J1: COEF. VARIACION
A2: ='Hoja 1'!C2 -> 14.645 | B2: ='Hoja 2'!C2 -> 13 | C2: ='Hoja 3'!C2 -> 14.7 | D2: ='Hoja 4'!C2 -> 15.6 | E2: =AVERAGE(A2:D2) -> 14.48625 | F2: =_xlfn.STDEV.P(A2:D2) -> 0.93811894 | G2: =_xlfn.VAR.P(A2:D2) -> 0.88006715 | H2: =MAX(A2:D2) - MIN(A2:D2) -> 2.6 | I2: =MEDIAN(A2:D2) -> 14.6725 | J2: =_xlfn.STDEV.P(A2:D2)/AVERAGE(A2:D2)*100 -> 6.4759268
A3: ='Hoja 1'!C3 -> 14.594999 | B3: ='Hoja 2'!C3 -> 13 | C3: ='Hoja 3'!C3 -> 14.5 | D3: ='Hoja 4'!C3 -> 15.6 | E3: =AVERAGE(A3:D3) -> 14.42375 | F3: =_xlfn.STDEV.P(A3:D3) -> 0.92813907 | G3: =_xlfn.VAR.P(A3:D3) -> 0.86144213 | H3: =MAX(A3:D3) - MIN(A3:D3) -> 2.6 | I3: =MEDIAN(A3:D3) -> 14.5475 | J3: =_xlfn.STDEV.P(A3:D3)/AVERAGE(A3:D3)*100 -> 6.4347973
A4: ='Hoja 1'!C4 -> 14.495 | B4: ='Hoja 2'!C4 -> 13 | C4: ='Hoja 3'!C4 -> 14.1 | D4: ='Hoja 4'!C4 -> 15.6 | E4: =AVERAGE(A4:D4) -> 14.29875 | F4: =_xlfn.STDEV.P(A4:D4) -> 0.92978744 | G4: =_xlfn.VAR.P(A4:D4) -> 0.86450468 | H4: =MAX(A4:D4) - MIN(A4:D4) -> 2.6 | I4: =MEDIAN(A4:D4) -> 14.2975 | J4: =_xlfn.STDEV.P(A4:D4)/AVERAGE(A4:D4)*100 -> 6.5025785
A5: ='Hoja 1'!C5 -> 13.495 | B5: ='Hoja 2'!C5 -> 13 | C5: ='Hoja 3'!C5 -> 13.8 | D5: ='Hoja 4'!C5 -> 15.2 | E5: =AVERAGE(A5:D5) -> 13.87375 | F5: =_xlfn.STDEV.P(A5:D5) -> 0.81720084 | G5: =_xlfn.VAR.P(A5:D5) -> 0.66781721 | H5: =MAX(A5:D5) - MIN(A5:D5) -> 2.2 | I5: =MEDIAN(A5:D5) -> 13.6475 | J5: =_xlfn.STDEV.P(A5:D5)/AVERAGE(A5:D5)*100 -> 5.8902664
A6: ='Hoja 1'!C6 -> 12.645 | B6: ='Hoja 2'!C6 -> 13 | C6: ='Hoja 3'!C6 -> 13.7 | D6: ='Hoja 4'!C6 -> 15.2 | E6: =AVERAGE(A6:D6) -> 13.63625 | F6: =_xlfn.STDEV.P(A6:D6) -> 0.9793837 | G6: =_xlfn.VAR.P(A6:D6) -> 0.95919243 | H6: =MAX(A6:D6) - MIN(A6:D6) -> 2.5550005 | I6: =MEDIAN(A6:D6) -> 13.35 | J6: =_xlfn.STDEV.P(A6:D6)/AVERAGE(A6:D6)*100 -> 7.1822071
A7: ='Hoja 1'!C7 -> 12.395 | B7: ='Hoja 2'!C7 -> 13 | C7: ='Hoja 3'!C7 -> 13.6 | D7: ='Hoja 4'!C7 -> 14.8 | E7: =AVERAGE(A7:D7) -> 13.44875 | F7: =_xlfn.STDEV.P(A7:D7) -> 0.88889254 | G7: =_xlfn.VAR.P(A7:D7) -> 0.79012995 | H7: =MAX(A7:D7) - MIN(A7:D7) -> 2.4050005 | I7: =MEDIAN(A7:D7) -> 13.3 | J7: =_xlfn.STDEV.P(A7:D7)/AVERAGE(A7:D7)*100 -> 6.6094808
A8: ='Hoja 1'!C8 -> 13.795 | B8: ='Hoja 2'!C8 -> 13 | C8: ='Hoja 3'!C8 -> 14 | D8: ='Hoja 4'!C8 -> 14.8 | E8: =AVERAGE(A8:D8) -> 13.89875 | F8: =_xlfn.STDEV.P(A8:D8) -> 0.64051127 | G8: =_xlfn.VAR.P(A8:D8) -> 0.41025468 | H8: =MAX(A8:D8) - MIN(A8:D8) -> 1.8 | I8: =MEDIAN(A8:D8) -> 13.8975 | J8: =_xlfn.STDEV.P(A8:D8)/AVERAGE(A8:D8)*100 -> 4.6084091
A9: ='Hoja 1'!C9 -> 14.945 | B9: ='Hoja 2'!C9 -> 14 | C9: ='Hoja 3'!C9 -> 16.1 | D9: ='Hoja 4'!C9 -> 14.8 | E9: =AVERAGE(A9:D9) -> 14.96125 | F9: =_xlfn.STDEV.P(A9:D9) -> 0.74950296 | G9: =_xlfn.VAR.P(A9:D9) -> 0.56175469 | H9: =MAX(A9:D9) - MIN(A9:D9) -> 2.1 | I9: =MEDIAN(A9:D9) -> 14.8725 | J9: =_xlfn.STDEV.P(A9:D9)/AVERAGE(A9:D9)*100 -> 5.009628
A10: ='Hoja 1'!C10 -> 15.795 | B10: ='Hoja 2'!C10 -> 14 | C10: ='Hoja 3'!C10 -> 16.3 | D10: ='Hoja 4'!C10 -> 15.2 | E10: =AVERAGE(A10:D10) -> 15.32375 | F10: =_xlfn.STDEV.P(A10:D10) -> 0.85772502 | G10: =_xlfn.VAR.P(A10:D10) -> 0.73569221 | H10: =MAX(A10:D10) - MIN(A10:D10) -> 2.3 | I10: =MEDIAN(A10:D10) -> 15.4975 | J10: =_xlfn.STDEV.P(A10:D10)/AVERAGE(A10:D10)*100 -> 5.5973572
A11: ='Hoja 1'!C11 -> 16.545 | B11: ='Hoja 2'!C11 -> 15 | C11: ='Hoja 3'!C11 -> 16.5 | D11: ='Hoja 4'!C11 -> 15.6 | E11: =AVERAGE(A11:D11) -> 15.91125 | F11: =_xlfn.STDEV.P(A11:D11) -> 0.64720917 | G11: =_xlfn.VAR.P(A11:D11) -> 0.41887971 | H11: =MAX(A11:D11) - MIN(A11:D11) -> 1.5450001 | I11: =MEDIAN(A11:D11) -> 16.05 | J11: =_xlfn.STDEV.P(A11:D11)/AVERAGE(A11:D11)*100 -> 4.0676199
A12: ='Hoja 1'!C12 -> 16.594999 | B12: ='Hoja 2'!C12 -> 16 | C12: ='Hoja 3'!C12 -> 16.2 | D12: ='Hoja 4'!C12 -> 15.9 | E12: =AVERAGE(A12:D12) -> 16.17375 | F12: =_xlfn.STDEV.P(A12:D12) -> 0.26611472 | G12: =_xlfn.VAR.P(A12:D12) -> 0.070817043 | H12: =MAX(A12:D12) - MIN(A12:D12) -> 0.69499931 | I12: =MEDIAN(A12:D12) -> 16.1 | J12: =_xlfn.STDEV.P(A12:D12)/AVERAGE(A12:D12)*100 -> 1.6453495
A13: ='Hoja 1'!C13 -> 15.995 | B13: ='Hoja 2'!C13 -> 16 | C13: ='Hoja 3'!C13 -> 16.5 | D13: ='Hoja 4'!C13 -> 15.9 | E13: =AVERAGE(A13:D13) -> 16.09875 | F13: =_xlfn.STDEV.P(A13:D13) -> 0.23506317 | G13: =_xlfn.VAR.P(A13:D13) -> 0.055254693 | H13: =MAX(A13:D13) - MIN(A13:D13) -> 0.6 | I13: =MEDIAN(A13:D13) -> 15.9975 | J13: =_xlfn.STDEV.P(A13:D13)/AVERAGE(A13:D13)*100 -> 1.4601331
... A457: ='Hoja 1'!C457 -> 16.994999 | B457: ='Hoja 2'!C457 -> 15 | C457: ='Hoja 3'!C457 -> 16.4 | D457: ='Hoja 4'!C457 -> 17.4 | E457: =AVERAGE(A457:D457) -> 16.44875 | F457: =_xlfn.STDEV.P(A457:D457) -> 0.90891661 | G457: =_xlfn.VAR.P(A457:D457) -> 0.8261294 | H457: =MAX(A457:D457) - MIN(A457:D457) -> 2.4 | I457: =MEDIAN(A457:D457) -> 16.697499 | J457: =_xlfn.STDEV.P(A457:D457)/AVERAGE(A457:D457)*100 -> 5.5257489
E458: =AVERAGE(E2:E457) -> 17.186277 | F458: =AVERAGE(F2:F457) -> 0.97929592 | G458: =AVERAGE(G2:G457) -> 1.166656 | H458: =AVERAGE(H2:H457) -> 2.52307 | I458: =AVERAGE(I2:I457) -> 17.189978 | J458: =AVERAGE(J2:J457) -> 5.6629621

Sheet AnalisisWindSpeed
A1: ='Hoja 1'!D1 -> velviento | B1: ='Hoja 2'!D1 -> velviento | C1: ='Hoja 3'!D1 -> velviento | D1: ='Hoja 4'!D1 -> velviento | E1: MEDIA | F1: DESVI. TIPICA | G1: VARIANZA | H1: RANGO | I1: MEDIANA | J1: COEF. VARIACION
A2: ='Hoja 1'!D2 -> 3.5455887 | B2: ='Hoja 2'!D2 -> 6 | C2: ='Hoja 3'!D2 -> 9 | D2: ='Hoja 4'!D2 -> 2.8 | E2: =AVERAGE(A2:D2) -> 5.3363972 | F2: =_xlfn.STDEV.P(A2:D2) -> 2.4239771 | G2: =_xlfn.VAR.P(A2:D2) -> 5.875665 | H2: =MAX(A2:D2) - MIN(A2:D2) -> 6.2 | I2: =MEDIAN(A2:D2) -> 4.7727944 | J2: =_xlfn.STDEV.P(A2:D2)/AVERAGE(A2:D2)*100 -> 45.423476
A3: ='Hoja 1'!D3 -> 4.0249224 | B3: ='Hoja 2'!D3 -> 5 | C3: ='Hoja 3'!D3 -> 7.4 | D3: ='Hoja 4'!D3 -> 2.4 | E3: =AVERAGE(A3:D3) -> 4.7062306 | F3: =_xlfn.STDEV.P(A3:D3) -> 1.8114617 | G3: =_xlfn.VAR.P(A3:D3) -> 3.2813936 | H3: =MAX(A3:D3) - MIN(A3:D3) -> 5 | I3: =MEDIAN(A3:D3) -> 4.5124612 | J3: =_xlfn.STDEV.P(A3:D3)/AVERAGE(A3:D3)*100 -> 38.490714
A4: ='Hoja 1'!D4 -> 5.7712388 | B4: ='Hoja 2'!D4 -> 6 | C4: ='Hoja 3'!D4 -> 7.4 | D4: ='Hoja 4'!D4 -> 2.4 | E4: =AVERAGE(A4:D4) -> 5.3928097 | F4: =_xlfn.STDEV.P(A4:D4) -> 1.8369548 | G4: =_xlfn.VAR.P(A4:D4) -> 3.3744029 | H4: =MAX(A4:D4) - MIN(A4:D4) -> 5 | I4: =MEDIAN(A4:D4) -> 5.8856194 | J4: =_xlfn.STDEV.P(A4:D4)/AVERAGE(A4:D4)*100 -> 34.063037
A5: ='Hoja 1'!D5 -> 6.1936741 | B5: ='Hoja 2'!D5 -> 6 | C5: ='Hoja 3'!D5 -> 7.4 | D5: ='Hoja 4'!D5 -> 2.8 | E5: =AVERAGE(A5:D5) -> 5.5984185 | F5: =_xlfn.STDEV.P(A5:D5) -> 1.7023835 | G5: =_xlfn.VAR.P(A5:D5) -> 2.8981097 | H5: =MAX(A5:D5) - MIN(A5:D5) -> 4.6 | I5: =MEDIAN(A5:D5) -> 6.096837 | J5: =_xlfn.STDEV.P(A5:D5)/AVERAGE(A5:D5)*100 -> 30.408294
A6: ='Hoja 1'!D6 -> 5.6233797 | B6: ='Hoja 2'!D6 -> 6 | C6: ='Hoja 3'!D6 -> 7.4 | D6: ='Hoja 4'!D6 -> 3.6 | E6: =AVERAGE(A6:D6) -> 5.6558449 | F6: =_xlfn.STDEV.P(A6:D6) -> 1.3590504 | G6: =_xlfn.VAR.P(A6:D6) -> 1.847018 | H6: =MAX(A6:D6) - MIN(A6:D6) -> 3.8 | I6: =MEDIAN(A6:D6) -> 5.8116899 | J6: =_xlfn.STDEV.P(A6:D6)/AVERAGE(A6:D6)*100 -> 24.029131
A7: ='Hoja 1'!D7 -> 7.1457958 | B7: ='Hoja 2'!D7 -> 7 | C7: ='Hoja 3'!D7 -> 7.4 | D7: ='Hoja 4'!D7 -> 3.6 | E7: =AVERAGE(A7:D7) -> 6.286449 | F7: =_xlfn.STDEV.P(A7:D7) -> 1.5576132 | G7: =_xlfn.VAR.P(A7:D7) -> 2.426159 | H7: =MAX(A7:D7) - MIN(A7:D7) -> 3.8 | I7: =MEDIAN(A7:D7) -> 7.0728979 | J7: =_xlfn.STDEV.P(A7:D7)/AVERAGE(A7:D7)*100 -> 24.777315
A8: ='Hoja 1'!D8 -> 4.0249224 | B8: ='Hoja 2'!D8 -> 6 | C8: ='Hoja 3'!D8 -> 8 | D8: ='Hoja 4'!D8 -> 3.2 | E8: =AVERAGE(A8:D8) -> 5.3062306 | F8: =_xlfn.STDEV.P(A8:D8) -> 1.8584717 | G8: =_xlfn.VAR.P(A8:D8) -> 3.4539169 | H8: =MAX(A8:D8) - MIN(A8:D8) -> 4.8 | I8: =MEDIAN(A8:D8) -> 5.0124612 | J8: =_xlfn.STDEV.P(A8:D8)/AVERAGE(A8:D8)*100 -> 35.024329
A9: ='Hoja 1'!D9 -> 4.6102495 | B9: ='Hoja 2'!D9 -> 6 | C9: ='Hoja 3'!D9 -> 7.4 | D9: ='Hoja 4'!D9 -> 2.8 | E9: =AVERAGE(A9:D9) -> 5.2025624 | F9: =_xlfn.STDEV.P(A9:D9) -> 1.7020414 | G9: =_xlfn.VAR.P(A9:D9) -> 2.8969448 | H9: =MAX(A9:D9) - MIN(A9:D9) -> 4.6 | I9: =MEDIAN(A9:D9) -> 5.3051248 | J9: =_xlfn.STDEV.P(A9:D9)/AVERAGE(A9:D9)*100 -> 32.715444
A10: ='Hoja 1'!D10 -> 6.5693827 | B10: ='Hoja 2'!D10 -> 6 | C10: ='Hoja 3'!D10 -> 7.4 | D10: ='Hoja 4'!D10 -> 3.2 | E10: =AVERAGE(A10:D10) -> 5.7923457 | F10: =_xlfn.STDEV.P(A10:D10) -> 1.577317 | G10: =_xlfn.VAR.P(A10:D10) -> 2.4879288 | H10: =MAX(A10:D10) - MIN(A10:D10) -> 4.2 | I10: =MEDIAN(A10:D10) -> 6.2846913 | J10: =_xlfn.STDEV.P(A10:D10)/AVERAGE(A10:D10)*100 -> 27.231057
A11: ='Hoja 1'!D11 -> 5.9372721 | B11: ='Hoja 2'!D11 -> 7 | C11: ='Hoja 3'!D11 -> 9.3 | D11: ='Hoja 4'!D11 -> 3.6 | E11: =AVERAGE(A11:D11) -> 6.459318 | F11: =_xlfn.STDEV.P(A11:D11) -> 2.0500026 | G11: =_xlfn.VAR.P(A11:D11) -> 4.2025107 | H11: =MAX(A11:D11) - MIN(A11:D11) -> 5.7 | I11: =MEDIAN(A11:D11) -> 6.468636 | J11: =_xlfn.STDEV.P(A11:D11)/AVERAGE(A11:D11)*100 -> 31.737137
A12: ='Hoja 1'!D12 -> 5.5069408 | B12: ='Hoja 2'!D12 -> 8 | C12: ='Hoja 3'!D12 -> 11.1 | D12: ='Hoja 4'!D12 -> 3.2 | E12: =AVERAGE(A12:D12) -> 6.9517352 | F12: =_xlfn.STDEV.P(A12:D12) -> 2.9355539 | G12: =_xlfn.VAR.P(A12:D12) -> 8.6174769 | H12: =MAX(A12:D12) - MIN(A12:D12) -> 7.9 | I12: =MEDIAN(A12:D12) -> 6.7534704 | J12: =_xlfn.STDEV.P(A12:D12)/AVERAGE(A12:D12)*100 -> 42.227643
A13: ='Hoja 1'!D13 -> 5.3999996 | B13: ='Hoja 2'!D13 -> 11 | C13: ='Hoja 3'!D13 -> 11.1 | D13: ='Hoja 4'!D13 -> 3.2 | E13: =AVERAGE(A13:D13) -> 7.6749999 | F13: =_xlfn.STDEV.P(A13:D13) -> 3.4636506 | G13: =_xlfn.VAR.P(A13:D13) -> 11.996875 | H13: =MAX(A13:D13) - MIN(A13:D13) -> 7.9 | I13: =MEDIAN(A13:D13) -> 8.1999998 | J13: =_xlfn.STDEV.P(A13:D13)/AVERAGE(A13:D13)*100 -> 45.128999
... A457: ='Hoja 1'!D457 -> 12.181624 | B457: ='Hoja 2'!D457 -> 4 | C457: ='Hoja 3'!D457 -> 14.8 | D457: ='Hoja 4'!D457 -> 6 | E457: =AVERAGE(A457:D457) -> 9.2454061 | F457: =_xlfn.STDEV.P(A457:D457) -> 4.4023243 | G457: =_xlfn.VAR.P(A457:D457) -> 19.380459 | H457: =MAX(A457:D457) - MIN(A457:D457) -> 10.8 | I457: =MEDIAN(A457:D457) -> 9.0908122 | J457: =_xlfn.STDEV.P(A457:D457)/AVERAGE(A457:D457)*100 -> 47.616343
E458: =AVERAGE(E2:E457) -> 8.6075309 | F458: =AVERAGE(F2:F457) -> 3.9972051 | G458: =AVERAGE(G2:G457) -> 18.325648 | H458: =AVERAGE(H2:H457) -> 10.189067 | I458: =AVERAGE(I2:I457) -> 8.452393 | J458: =AVERAGE(J2:J457) -> 48.063404

Sheet AnalisisWindDirection
A1: ='Hoja 1'!E1 -> dirviento | B1: ='Hoja 2'!E1 -> dirviento | C1: ='Hoja 2'!E1 -> dirviento | D1: ='Hoja 2'!E1 -> dirviento | E1: MEDIA | F1: DESVI. TIPICA | G1: VARIANZA | H1: RANGO | I1: MEDIANA | J1: COEF. VARIACION
A2: ='Hoja 1'!E2 -> 23.962492 | B2: ='Hoja 2'!E2 -> 318 | C2: ='Hoja 3'!E2 -> 30 | D2: ='Hoja 4'!E2 -> 358 | E2: =AVERAGE(A2:D2) -> 182.49062 | F2: =_xlfn.STDEV.P(A2:D2) -> 156.16569 | G2: =_xlfn.VAR.P(A2:D2) -> 24387.723 | H2: =MAX(A2:D2) - MIN(A2:D2) -> 334.03751 | I2: =MEDIAN(A2:D2) -> 174 | J2: =_xlfn.STDEV.P(A2:D2)/AVERAGE(A2:D2)*100 -> 85.574638
A3: ='Hoja 1'!E3 -> 10.304792 | B3: ='Hoja 2'!E3 -> 315 | C3: ='Hoja 3'!E3 -> 347 | D3: ='Hoja 4'!E3 -> 348 | E3: =AVERAGE(A3:D3) -> 255.0762 | F3: =_xlfn.STDEV.P(A3:D3) -> 141.94076 | G3: =_xlfn.VAR.P(A3:D3) -> 20147.18 | H3: =MAX(A3:D3) - MIN(A3:D3) -> 337.69521 | I3: =MEDIAN(A3:D3) -> 331 | J3: =_xlfn.STDEV.P(A3:D3)/AVERAGE(A3:D3)*100 -> 55.646416
A4: ='Hoja 1'!E4 -> 356.42374 | B4: ='Hoja 2'!E4 -> 312 | C4: ='Hoja 3'!E4 -> 260 | D4: ='Hoja 4'!E4 -> 332 | E4: =AVERAGE(A4:D4) -> 315.10593 | F4: =_xlfn.STDEV.P(A4:D4) -> 35.492538 | G4: =_xlfn.VAR.P(A4:D4) -> 1259.7203 | H4: =MAX(A4:D4) - MIN(A4:D4) -> 96.423737 | I4: =MEDIAN(A4:D4) -> 322 | J4: =_xlfn.STDEV.P(A4:D4)/AVERAGE(A4:D4)*100 -> 11.263684
A5: ='Hoja 1'!E5 -> 215.53777 | B5: ='Hoja 2'!E5 -> 301 | C5: ='Hoja 3'!E5 -> 219 | D5: ='Hoja 4'!E5 -> 320 | E5: =AVERAGE(A5:D5) -> 263.88444 | F5: =_xlfn.STDEV.P(A5:D5) -> 47.112989 | G5: =_xlfn.VAR.P(A5:D5) -> 2219.6337 | H5: =MAX(A5:D5) - MIN(A5:D5) -> 104.46223 | I5: =MEDIAN(A5:D5) -> 260 | J5: =_xlfn.STDEV.P(A5:D5)/AVERAGE(A5:D5)*100 -> 17.853644
A6: ='Hoja 1'!E6 -> 230.19447 | B6: ='Hoja 2'!E6 -> 297 | C6: ='Hoja 3'!E6 -> 228 | D6: ='Hoja 4'!E6 -> 322 | E6: =AVERAGE(A6:D6) -> 269.29862 | F6: =_xlfn.STDEV.P(A6:D6) -> 41.168897 | G6: =_xlfn.VAR.P(A6:D6) -> 1694.8781 | H6: =MAX(A6:D6) - MIN(A6:D6) -> 94 | I6: =MEDIAN(A6:D6) -> 263.59724 | J6: =_xlfn.STDEV.P(A6:D6)/AVERAGE(A6:D6)*100 -> 15.287452
A7: ='Hoja 1'!E7 -> 229.08571 | B7: ='Hoja 2'!E7 -> 291 | C7: ='Hoja 3'!E7 -> 226 | D7: ='Hoja 4'!E7 -> 326 | E7: =AVERAGE(A7:D7) -> 268.02143 | F7: =_xlfn.STDEV.P(A7:D7) -> 42.341824 | G7: =_xlfn.VAR.P(A7:D7) -> 1792.8301 | H7: =MAX(A7:D7) - MIN(A7:D7) -> 100 | I7: =MEDIAN(A7:D7) -> 260.04285 | J7: =_xlfn.STDEV.P(A7:D7)/AVERAGE(A7:D7)*100 -> 15.797925
A8: ='Hoja 1'!E8 -> 206.56499 | B8: ='Hoja 2'!E8 -> 284 | C8: ='Hoja 3'!E8 -> 210 | D8: ='Hoja 4'!E8 -> 328 | E8: =AVERAGE(A8:D8) -> 257.14125 | F8: =_xlfn.STDEV.P(A8:D8) -> 51.289889 | G8: =_xlfn.VAR.P(A8:D8) -> 2630.6527 | H8: =MAX(A8:D8) - MIN(A8:D8) -> 121.43501 | I8: =MEDIAN(A8:D8) -> 247 | J8: =_xlfn.STDEV.P(A8:D8)/AVERAGE(A8:D8)*100 -> 19.946193
A9: ='Hoja 1'!E9 -> 231.34016 | B9: ='Hoja 2'!E9 -> 289 | C9: ='Hoja 3'!E9 -> 247 | D9: ='Hoja 4'!E9 -> 332 | E9: =AVERAGE(A9:D9) -> 274.83504 | F9: =_xlfn.STDEV.P(A9:D9) -> 39.163352 | G9: =_xlfn.VAR.P(A9:D9) -> 1533.7681 | H9: =MAX(A9:D9) - MIN(A9:D9) -> 100.65984 | I9: =MEDIAN(A9:D9) -> 268 | J9: =_xlfn.STDEV.P(A9:D9)/AVERAGE(A9:D9)*100 -> 14.249766
A10: ='Hoja 1'!E10 -> 279.46225 | B10: ='Hoja 2'!E10 -> 300 | C10: ='Hoja 3'!E10 -> 283 | D10: ='Hoja 4'!E10 -> 346 | E10: =AVERAGE(A10:D10) -> 302.11556 | F10: =_xlfn.STDEV.P(A10:D10) -> 26.499513 | G10: =_xlfn.VAR.P(A10:D10) -> 702.22419 | H10: =MAX(A10:D10) - MIN(A10:D10) -> 66.53775 | I10: =MEDIAN(A10:D10) -> 291.5 | J10: =_xlfn.STDEV.P(A10:D10)/AVERAGE(A10:D10)*100 -> 8.7713168
A11: ='Hoja 1'!E11 -> 284.03625 | B11: ='Hoja 2'!E11 -> 313 | C11: ='Hoja 3'!E11 -> 326 | D11: ='Hoja 4'!E11 -> 0 | E11: =AVERAGE(A11:D11) -> 230.75906 | F11: =_xlfn.STDEV.P(A11:D11) -> 134.09196 | G11: =_xlfn.VAR.P(A11:D11) -> 17980.653 | H11: =MAX(A11:D11) - MIN(A11:D11) -> 326 | I11: =MEDIAN(A11:D11) -> 298.51813 | J11: =_xlfn.STDEV.P(A11:D11)/AVERAGE(A11:D11)*100 -> 58.109075
A12: ='Hoja 1'!E12 -> 281.30991 | B12: ='Hoja 2'!E12 -> 333 | C12: ='Hoja 3'!E12 -> 316 | D12: ='Hoja 4'!E12 -> 2 | E12: =AVERAGE(A12:D12) -> 233.07748 | F12: =_xlfn.STDEV.P(A12:D12) -> 134.70693 | G12: =_xlfn.VAR.P(A12:D12) -> 18145.956 | H12: =MAX(A12:D12) - MIN(A12:D12) -> 331 | I12: =MEDIAN(A12:D12) -> 298.65495 | J12: =_xlfn.STDEV.P(A12:D12)/AVERAGE(A12:D12)*100 -> 57.794913
A13: ='Hoja 1'!E13 -> 360 | B13: ='Hoja 2'!E13 -> 345 | C13: ='Hoja 3'!E13 -> 334 | D13: ='Hoja 4'!E13 -> 4 | E13: =AVERAGE(A13:D13) -> 260.75 | F13: =_xlfn.STDEV.P(A13:D13) -> 148.52167 | G13: =_xlfn.VAR.P(A13:D13) -> 22058.688 | H13: =MAX(A13:D13) - MIN(A13:D13) -> 356 | I13: =MEDIAN(A13:D13) -> 339.5 | J13: =_xlfn.STDEV.P(A13:D13)/AVERAGE(A13:D13)*100 -> 56.959415
... A457: ='Hoja 1'!E457 -> 235.84026 | B457: ='Hoja 2'!E457 -> 271 | C457: ='Hoja 3'!E457 -> 260 | D457: ='Hoja 4'!E457 -> 274 | E457: =AVERAGE(A457:D457) -> 260.21006 | F457: =_xlfn.STDEV.P(A457:D457) -> 15.004306 | G457: =_xlfn.VAR.P(A457:D457) -> 225.12918 | H457: =MAX(A457:D457) - MIN(A457:D457) -> 38.159744 | I457: =MEDIAN(A457:D457) -> 265.5 | J457: =_xlfn.STDEV.P(A457:D457)/AVERAGE(A457:D457)*100 -> 5.766228
E458: =AVERAGE(E2:E457) -> 185.72856 | F458: =AVERAGE(F2:F457) -> 43.452032 | G458: =AVERAGE(G2:G457) -> 3733.2908 | H458: =AVERAGE(H2:H457) -> 107.30133 | I458: =AVERAGE(I2:I457) -> 182.38626 | J458: =AVERAGE(J2:J457) -> 34.233199

Sheet AnalisisRadiation
A1: ='Hoja 1'!F1 -> direct_radiation_openmeteo | D1: ='Hoja 4'!#REF! -> #REF! | E1: MEDIA | F1: DESVI. TIPICA | G1: VARIANZA | H1: RANGO | I1: MEDIANA | J1: COEF. VARIACION
A2: ='Hoja 1'!F2 -> 0 | D2: ='Hoja 4'!#REF! -> #REF! | E2: =AVERAGE(A2:D2) -> #REF! | F2: =_xlfn.STDEV.P(A2:D2) -> #REF! | G2: =_xlfn.VAR.P(A2:D2) -> #REF! | H2: =MAX(A2:D2) - MIN(A2:D2) -> #REF! | I2: =MEDIAN(A2:D2) -> #REF! | J2: =_xlfn.STDEV.P(A2:D2)/AVERAGE(A2:D2)*100 -> #REF!
A3: ='Hoja 1'!F3 -> 0 | D3: ='Hoja 4'!#REF! -> #REF! | E3: =AVERAGE(A3:D3) -> #REF! | F3: =_xlfn.STDEV.P(A3:D3) -> #REF! | G3: =_xlfn.VAR.P(A3:D3) -> #REF! | H3: =MAX(A3:D3) - MIN(A3:D3) -> #REF! | I3: =MEDIAN(A3:D3) -> #REF! | J3: =_xlfn.STDEV.P(A3:D3)/AVERAGE(A3:D3)*100 -> #REF!
A4: ='Hoja 1'!F4 -> 0 | D4: ='Hoja 4'!#REF! -> #REF! | E4: =AVERAGE(A4:D4) -> #REF! | F4: =_xlfn.STDEV.P(A4:D4) -> #REF! | G4: =_xlfn.VAR.P(A4:D4) -> #REF! | H4: =MAX(A4:D4) - MIN(A4:D4) -> #REF! | I4: =MEDIAN(A4:D4) -> #REF! | J4: =_xlfn.STDEV.P(A4:D4)/AVERAGE(A4:D4)*100 -> #REF!
A5: ='Hoja 1'!F5 -> 0 | D5: ='Hoja 4'!#REF! -> #REF! | E5: =AVERAGE(A5:D5) -> #REF! | F5: =_xlfn.STDEV.P(A5:D5) -> #REF! | G5: =_xlfn.VAR.P(A5:D5) -> #REF! | H5: =MAX(A5:D5) - MIN(A5:D5) -> #REF! | I5: =MEDIAN(A5:D5) -> #REF! | J5: =_xlfn.STDEV.P(A5:D5)/AVERAGE(A5:D5)*100 -> #REF!
A6: ='Hoja 1'!F6 -> 0 | D6: ='Hoja 4'!#REF! -> #REF! | E6: =AVERAGE(A6:D6) -> #REF! | F6: =_xlfn.STDEV.P(A6:D6) -> #REF! | G6: =_xlfn.VAR.P(A6:D6) -> #REF! | H6: =MAX(A6:D6) - MIN(A6:D6) -> #REF! | I6: =MEDIAN(A6:D6) -> #REF! | J6: =_xlfn.STDEV.P(A6:D6)/AVERAGE(A6:D6)*100 -> #REF!
A7: ='Hoja 1'!F7 -> 0.033950329 | D7: ='Hoja 4'!#REF! -> #REF! | E7: =AVERAGE(A7:D7) -> #REF! | F7: =_xlfn.STDEV.P(A7:D7) -> #REF! | G7: =_xlfn.VAR.P(A7:D7) -> #REF! | H7: =MAX(A7:D7) - MIN(A7:D7) -> #REF! | I7: =MEDIAN(A7:D7) -> #REF! | J7: =_xlfn.STDEV.P(A7:D7)/AVERAGE(A7:D7)*100 -> #REF!
A8: ='Hoja 1'!F8 -> 51.700218 | D8: ='Hoja 4'!#REF! -> #REF! | E8: =AVERAGE(A8:D8) -> #REF! | F8: =_xlfn.STDEV.P(A8:D8) -> #REF! | G8: =_xlfn.VAR.P(A8:D8) -> #REF! | H8: =MAX(A8:D8) - MIN(A8:D8) -> #REF! | I8: =MEDIAN(A8:D8) -> #REF! | J8: =_xlfn.STDEV.P(A8:D8)/AVERAGE(A8:D8)*100 -> #REF!
A9: ='Hoja 1'!F9 -> 4.1932335 | D9: ='Hoja 4'!#REF! -> #REF! | E9: =AVERAGE(A9:D9) -> #REF! | F9: =_xlfn.STDEV.P(A9:D9) -> #REF! | G9: =_xlfn.VAR.P(A9:D9) -> #REF! | H9: =MAX(A9:D9) - MIN(A9:D9) -> #REF! | I9: =MEDIAN(A9:D9) -> #REF! | J9: =_xlfn.STDEV.P(A9:D9)/AVERAGE(A9:D9)*100 -> #REF!
A10: ='Hoja 1'!F10 -> 5.4483795 | D10: ='Hoja 4'!#REF! -> #REF! | E10: =AVERAGE(A10:D10) -> #REF! | F10: =_xlfn.STDEV.P(A10:D10) -> #REF! | G10: =_xlfn.VAR.P(A10:D10) -> #REF! | H10: =MAX(A10:D10) - MIN(A10:D10) -> #REF! | I10: =MEDIAN(A10:D10) -> #REF! | J10: =_xlfn.STDEV.P(A10:D10)/AVERAGE(A10:D10)*100 -> #REF!
A11: ='Hoja 1'!F11 -> 0.28465652 | D11: ='Hoja 4'!#REF! -> #REF! | E11: =AVERAGE(A11:D11) -> #REF! | F11: =_xlfn.STDEV.P(A11:D11) -> #REF! | G11: =_xlfn.VAR.P(A11:D11) -> #REF! | H11: =MAX(A11:D11) - MIN(A11:D11) -> #REF! | I11: =MEDIAN(A11:D11) -> #REF! | J11: =_xlfn.STDEV.P(A11:D11)/AVERAGE(A11:D11)*100 -> #REF!
A12: ='Hoja 1'!F12 -> -0.31522751 | D12: ='Hoja 4'!#REF! -> #REF! | E12: =AVERAGE(A12:D12) -> #REF! | F12: =_xlfn.STDEV.P(A12:D12) -> #REF! | G12: =_xlfn.VAR.P(A12:D12) -> #REF! | H12: =MAX(A12:D12) - MIN(A12:D12) -> #REF! | I12: =MEDIAN(A12:D12) -> #REF! | J12: =_xlfn.STDEV.P(A12:D12)/AVERAGE(A12:D12)*100 -> #REF!
A13: ='Hoja 1'!F13 -> 0.15647507 | D13: ='Hoja 4'!#REF! -> #REF! | E13: =AVERAGE(A13:D13) -> #REF! | F13: =_xlfn.STDEV.P(A13:D13) -> #REF! | G13: =_xlfn.VAR.P(A13:D13) -> #REF! | H13: =MAX(A13:D13) - MIN(A13:D13) -> #REF! | I13: =MEDIAN(A13:D13) -> #REF! | J13: =_xlfn.STDEV.P(A13:D13)/AVERAGE(A13:D13)*100 -> #REF!
... A22: ='Hoja 1'!F22 -> 9.9460201 | D22: ='Hoja 4'!#REF! -> #REF! | E22: =AVERAGE(A22:D22) -> #REF! | F22: =_xlfn.STDEV.P(A22:D22) -> #REF! | G22: =_xlfn.VAR.P(A22:D22) -> #REF! | H22: =MAX(A22:D22) - MIN(A22:D22) -> #REF! | I22: =MEDIAN(A22:D22) -> #REF! | J22: =_xlfn.STDEV.P(A22:D22)/AVERAGE(A22:D22)*100 -> #REF!
A23: ='Hoja 1'!F23 -> 0 | D23: ='Hoja 4'!#REF! -> #REF! | E23: =AVERAGE(A23:D23) -> #REF! | F23: =_xlfn.STDEV.P(A23:D23) -> #REF! | G23: =_xlfn.VAR.P(A23:D23) -> #REF! | H23: =MAX(A23:D23) - MIN(A23:D23) -> #REF! | I23: =MEDIAN(A23:D23) -> #REF!
A24: ='Hoja 1'!F24 -> 0 | D24: ='Hoja 4'!#REF! -> #REF! | E24: =AVERAGE(A24:D24) -> #REF! | F24: =_xlfn.STDEV.P(A24:D24) -> #REF! | G24: =_xlfn.VAR.P(A24:D24) -> #REF! | H24: =MAX(A24:D24) - MIN(A24:D24) -> #REF! | I24: =MEDIAN(A24:D24) -> #REF!
A25: ='Hoja 1'!F25 -> 0 | D25: ='Hoja 4'!#REF! -> #REF! | E25: =AVERAGE(A25:D25) -> #REF! | F25: =_xlfn.STDEV.P(A25:D25) -> #REF! | G25: =_xlfn.VAR.P(A25:D25) -> #REF! | H25: =MAX(A25:D25) - MIN(A25:D25) -> #REF! | I25: =MEDIAN(A25:D25) -> #REF!
A26: ='Hoja 1'!F26 -> 0 | D26: ='Hoja 4'!#REF! -> #REF! | E26: =AVERAGE(A26:D26) -> #REF! | F26: =_xlfn.STDEV.P(A26:D26) -> #REF! | G26: =_xlfn.VAR.P(A26:D26) -> #REF! | H26: =MAX(A26:D26) - MIN(A26:D26) -> #REF! | I26: =MEDIAN(A26:D26) -> #REF!
A27: ='Hoja 1'!F27 -> 0 | D27: ='Hoja 4'!#REF! -> #REF! | E27: =AVERAGE(A27:D27) -> #REF! | F27: =_xlfn.STDEV.P(A27:D27) -> #REF! | G27: =_xlfn.VAR.P(A27:D27) -> #REF! | H27: =MAX(A27:D27) - MIN(A27:D27) -> #REF! | I27: =MEDIAN(A27:D27) -> #REF!
A28: ='Hoja 1'!F28 -> 0 | D28: ='Hoja 4'!#REF! -> #REF! | E28: =AVERAGE(A28:D28) -> #REF! | F28: =_xlfn.STDEV.P(A28:D28) -> #REF! | G28: =_xlfn.VAR.P(A28:D28) -> #REF! | H28: =MAX(A28:D28) - MIN(A28:D28) -> #REF! | I28: =MEDIAN(A28:D28) -> #REF!
A29: ='Hoja 1'!F29 -> 0 | D29: ='Hoja 4'!#REF! -> #REF! | E29: =AVERAGE(A29:D29) -> #REF! | F29: =_xlfn.STDEV.P(A29:D29) -> #REF! | G29: =_xlfn.VAR.P(A29:D29) -> #REF! | H29: =MAX(A29:D29) - MIN(A29:D29) -> #REF! | I29: =MEDIAN(A29:D29) -> #REF!
A30: ='Hoja 1'!F30 -> 0 | D30: ='Hoja 4'!#REF! -> #REF! | E30: =AVERAGE(A30:D30) -> #REF! | F30: =_xlfn.STDEV.P(A30:D30) -> #REF! | G30: =_xlfn.VAR.P(A30:D30) -> #REF! | H30: =MAX(A30:D30) - MIN(A30:D30) -> #REF! | I30: =MEDIAN(A30:D30) -> #REF!
A31: ='Hoja 1'!F31 -> -0.13902378 | D31: ='Hoja 4'!#REF! -> #REF! | E31: =AVERAGE(A31:D31) -> #REF! | F31: =_xlfn.STDEV.P(A31:D31) -> #REF! | G31: =_xlfn.VAR.P(A31:D31) -> #REF! | H31: =MAX(A31:D31) - MIN(A31:D31) -> #REF! | I31: =MEDIAN(A31:D31) -> #REF! | J31: =_xlfn.STDEV.P(A31:D31)/AVERAGE(A31:D31)*100 -> #REF!
A32: ='Hoja 1'!F32 -> -0.2179451 | D32: ='Hoja 4'!#REF! -> #REF! | E32: =AVERAGE(A32:D32) -> #REF! | F32: =_xlfn.STDEV.P(A32:D32) -> #REF! | G32: =_xlfn.VAR.P(A32:D32) -> #REF! | H32: =MAX(A32:D32) - MIN(A32:D32) -> #REF! | I32: =MEDIAN(A32:D32) -> #REF! | J32: =_xlfn.STDEV.P(A32:D32)/AVERAGE(A32:D32)*100 -> #REF!
A33: ='Hoja 1'!F33 -> 0.46948624 | D33: ='Hoja 4'!#REF! -> #REF! | E33: =AVERAGE(A33:D33) -> #REF! | F33: =_xlfn.STDEV.P(A33:D33) -> #REF! | G33: =_xlfn.VAR.P(A33:D33) -> #REF! | H33: =MAX(A33:D33) - MIN(A33:D33) -> #REF! | I33: =MEDIAN(A33:D33) -> #REF! | J33: =_xlfn.STDEV.P(A33:D33)/AVERAGE(A33:D33)*100 -> #REF!
A34: ='Hoja 1'!F34 -> 21.872894 | D34: ='Hoja 4'!#REF! -> #REF! | E34: =AVERAGE(A34:D34) -> #REF! | F34: =_xlfn.STDEV.P(A34:D34) -> #REF! | G34: =_xlfn.VAR.P(A34:D34) -> #REF! | H34: =MAX(A34:D34) - MIN(A34:D34) -> #REF! | I34: =MEDIAN(A34:D34) -> #REF! | J34: =_xlfn.STDEV.P(A34:D34)/AVERAGE(A34:D34)*100 -> #REF!
A35: ='Hoja 1'!F35 -> 194.81841 | D35: ='Hoja 4'!#REF! -> #REF! | E35: =AVERAGE(A35:D35) -> #REF! | F35: =_xlfn.STDEV.P(A35:D35) -> #REF! | G35: =_xlfn.VAR.P(A35:D35) -> #REF! | H35: =MAX(A35:D35) - MIN(A35:D35) -> #REF! | I35: =MEDIAN(A35:D35) -> #REF! | J35: =_xlfn.STDEV.P(A35:D35)/AVERAGE(A35:D35)*100 -> #REF!
A36: ='Hoja 1'!F36 -> 264.31003 | D36: ='Hoja 4'!#REF! -> #REF! | E36: =AVERAGE(A36:D36) -> #REF! | F36: =_xlfn.STDEV.P(A36:D36) -> #REF! | G36: =_xlfn.VAR.P(A36:D36) -> #REF! | H36: =MAX(A36:D36) - MIN(A36:D36) -> #REF! | I36: =MEDIAN(A36:D36) -> #REF! | J36: =_xlfn.STDEV.P(A36:D36)/AVERAGE(A36:D36)*100 -> #REF!
A37: ='Hoja 1'!F37 -> 811.68823 | D37: ='Hoja 4'!#REF! -> #REF! | E37: =AVERAGE(A37:D37) -> #REF! | F37: =_xlfn.STDEV.P(A37:D37) -> #REF! | G37: =_xlfn.VAR.P(A37:D37) -> #REF! | H37: =MAX(A37:D37) - MIN(A37:D37) -> #REF! | I37: =MEDIAN(A37:D37) -> #REF! | J37: =_xlfn.STDEV.P(A37:D37)/AVERAGE(A37:D37)*100 -> #REF!
A38: ='Hoja 1'!F38 -> 890.48816 | D38: ='Hoja 4'!#REF! -> #REF! | E38: =AVERAGE(A38:D38) -> #REF! | F38: =_xlfn.STDEV.P(A38:D38) -> #REF! | G38: =_xlfn.VAR.P(A38:D38) -> #REF! | H38: =MAX(A38:D38) - MIN(A38:D38) -> #REF! | I38: =MEDIAN(A38:D38) -> #REF! | J38: =_xlfn.STDEV.P(A38:D38)/AVERAGE(A38:D38)*100 -> #REF!
A39: ='Hoja 1'!F39 -> 928.48236 | D39: ='Hoja 4'!#REF! -> #REF! | E39: =AVERAGE(A39:D39) -> #REF! | F39: =_xlfn.STDEV.P(A39:D39) -> #REF! | G39: =_xlfn.VAR.P(A39:D39) -> #REF! | H39: =MAX(A39:D39) - MIN(A39:D39) -> #REF! | I39: =MEDIAN(A39:D39) -> #REF! | J39: =_xlfn.STDEV.P(A39:D39)/AVERAGE(A39:D39)*100 -> #REF!
A40: ='Hoja 1'!F40 -> 829.31677 | D40: ='Hoja 4'!#REF! -> #REF! | E40: =AVERAGE(A40:D40) -> #REF! | F40: =_xlfn.STDEV.P(A40:D40) -> #REF! | G40: =_xlfn.VAR.P(A40:D40) -> #REF! | H40: =MAX(A40:D40) - MIN(A40:D40) -> #REF! | I40: =MEDIAN(A40:D40) -> #REF! | J40: =_xlfn.STDEV.P(A40:D40)/AVERAGE(A40:D40)*100 -> #REF!
A41: ='Hoja 1'!F41 -> 791.37939 | D41: ='Hoja 4'!#REF! -> #REF! | E41: =AVERAGE(A41:D41) -> #REF! | F41: =_xlfn.STDEV.P(A41:D41) -> #REF! | G41: =_xlfn.VAR.P(A41:D41) -> #REF! | H41: =MAX(A41:D41) - MIN(A41:D41) -> #REF! | I41: =MEDIAN(A41:D41) -> #REF! | J41: =_xlfn.STDEV.P(A41:D41)/AVERAGE(A41:D41)*100 -> #REF!
A42: ='Hoja 1'!F42 -> 680.36951 | D42: ='Hoja 4'!#REF! -> #REF! | E42: =AVERAGE(A42:D42) -> #REF! | F42: =_xlfn.STDEV.P(A42:D42) -> #REF! | G42: =_xlfn.VAR.P(A42:D42) -> #REF! | H42: =MAX(A42:D42) - MIN(A42:D42) -> #REF! | I42: =MEDIAN(A42:D42) -> #REF! | J42: =_xlfn.STDEV.P(A42:D42)/AVERAGE(A42:D42)*100 -> #REF!
... A46: ='Hoja 1'!F46 -> 7.7721157 | D46: ='Hoja 4'!#REF! -> #REF! | E46: =AVERAGE(A46:D46) -> #REF! | F46: =_xlfn.STDEV.P(A46:D46) -> #REF! | G46: =_xlfn.VAR.P(A46:D46) -> #REF! | H46: =MAX(A46:D46) - MIN(A46:D46) -> #REF! | I46: =MEDIAN(A46:D46) -> #REF! | J46: =_xlfn.STDEV.P(A46:D46)/AVERAGE(A46:D46)*100 -> #REF!
A47: ='Hoja 1'!F47 -> 0 | D47: ='Hoja 4'!#REF! -> #REF! | E47: =AVERAGE(A47:D47) -> #REF! | F47: =_xlfn.STDEV.P(A47:D47) -> #REF! | G47: =_xlfn.VAR.P(A47:D47) -> #REF! | H47: =MAX(A47:D47) - MIN(A47:D47) -> #REF! | I47: =MEDIAN(A47:D47) -> #REF!
A48: ='Hoja 1'!F48 -> 0 | D48: ='Hoja 4'!#REF! -> #REF! | E48: =AVERAGE(A48:D48) -> #REF! | F48: =_xlfn.STDEV.P(A48:D48) -> #REF! | G48: =_xlfn.VAR.P(A48:D48) -> #REF! | H48: =MAX(A48:D48) - MIN(A48:D48) -> #REF! | I48: =MEDIAN(A48:D48) -> #REF!
A49: ='Hoja 1'!F49 -> 0 | D49: ='Hoja 4'!#REF! -> #REF! | E49: =AVERAGE(A49:D49) -> #REF! | F49: =_xlfn.STDEV.P(A49:D49) -> #REF! | G49: =_xlfn.VAR.P(A49:D49) -> #REF! | H49: =MAX(A49:D49) - MIN(A49:D49) -> #REF! | I49: =MEDIAN(A49:D49) -> #REF!
A50: ='Hoja 1'!F50 -> 0 | D50: ='Hoja 4'!#REF! -> #REF! | E50: =AVERAGE(A50:D50) -> #REF! | F50: =_xlfn.STDEV.P(A50:D50) -> #REF! | G50: =_xlfn.VAR.P(A50:D50) -> #REF! | H50: =MAX(A50:D50) - MIN(A50:D50) -> #REF! | I50: =MEDIAN(A50:D50) -> #REF!
A51: ='Hoja 1'!F51 -> 0 | D51: ='Hoja 4'!#REF! -> #REF! | E51: =AVERAGE(A51:D51) -> #REF! | F51: =_xlfn.STDEV.P(A51:D51) -> #REF! | G51: =_xlfn.VAR.P(A51:D51) -> #REF! | H51: =MAX(A51:D51) - MIN(A51:D51) -> #REF! | I51: =MEDIAN(A51:D51) -> #REF!
...
